Workbook

Sheet 2015
A1: Country | B1: Region | C1: Happiness Rank | D1: Happiness Score | E1: Standard Error | F1: Economy (GDP per Capita) | G1: Family | H1: Health (Life Expectancy) | I1: Freedom | J1: Trust (Government Corruption) | K1: Generosity | L1: Dystopia Residual | M1: Year
A2: Switzerland | B2: Western Europe | C2: 1 | D2: 7.587 | E2: 0.03411 | F2: 1.39651 | G2: 1.34951 | H2: 0.94143 | I2: 0.66557 | J2: 0.41978 | K2: 0.29678 | L2: 2.51738 | M2: 2015
A3: Iceland | B3: Western Europe | C3: 2 | D3: 7.561 | E3: 0.04884 | F3: 1.30232 | G3: 1.40223 | H3: 0.94784 | I3: 0.62877 | J3: 0.14145 | K3: 0.4363 | L3: 2.70201 | M3: 2015
A4: Denmark | B4: Western Europe | C4: 3 | D4: 7.527 | E4: 0.03328 | F4: 1.32548 | G4: 1.36058 | H4: 0.87464 | I4: 0.64938 | J4: 0.48357 | K4: 0.34139 | L4: 2.49204 | M4: 2015
A5: Norway | B5: Western Europe | C5: 4 | D5: 7.522 | E5: 0.0388 | F5: 1.459 | G5: 1.33095 | H5: 0.88521 | I5: 0.66973 | J5: 0.36503 | K5: 0.34699 | L5: 2.46531 | M5: 2015
A6: Canada | B6: North America | C6: 5 | D6: 7.427 | E6: 0.03553 | F6: 1.32629 | G6: 1.32261 | H6: 0.90563 | I6: 0.63297 | J6: 0.32957 | K6: 0.45811 | L6: 2.45176 | M6: 2015
A7: Finland | B7: Western Europe | C7: 6 | D7: 7.406 | E7: 0.0314 | F7: 1.29025 | G7: 1.31826 | H7: 0.88911 | I7: 0.64169 | J7: 0.41372 | K7: 0.23351 | L7: 2.61955 | M7: 2015
A8: Netherlands | B8: Western Europe | C8: 7 | D8: 7.378 | E8: 0.02799 | F8: 1.32944 | G8: 1.28017 | H8: 0.89284 | I8: 0.61576 | J8: 0.31814 | K8: 0.4761 | L8: 2.4657 | M8: 2015
A9: Sweden | B9: Western Europe | C9: 8 | D9: 7.364 | E9: 0.03157 | F9: 1.33171 | G9: 1.28907 | H9: 0.91087 | I9: 0.6598 | J9: 0.43844 | K9: 0.36262 | L9: 2.37119 | M9: 2015
A10: New Zealand | B10: Australia and New Zealand | C10: 9 | D10: 7.286 | E10: 0.03371 | F10: 1.25018 | G10: 1.31967 | H10: 0.90837 | I10: 0.63938 | J10: 0.42922 | K10: 0.47501 | L10: 2.26425 | M10: 2015
A11: Australia | B11: Australia and New Zealand | C11: 10 | D11: 7.284 | E11: 0.04083 | F11: 1.33358 | G11: 1.30923 | H11: 0.93156 | I11: 0.65124 | J11: 0.35637 | K11: 0.43562 | L11: 2.26646 | M11: 2015
A12: Israel | B12: Middle East and Northern Africa | C12: 11 | D12: 7.278 | E12: 0.0347 | F12: 1.22857 | G12: 1.22393 | H12: 0.91387 | I12: 0.41319 | J12: 0.07785 | K12: 0.33172 | L12: 3.08854 | M12: 2015
A13: Costa Rica | B13: Latin America and Caribbean | C13: 12 | D13: 7.226 | E13: 0.04454 | F13: 0.95578 | G13: 1.23788 | H13: 0.86027 | I13: 0.63376 | J13: 0.10583 | K13: 0.25497 | L13: 3.17728 | M13: 2015
... A159: Togo | B159: Sub-Saharan Africa | C159: 158 | D159: 2.839 | E159: 0.06727 | F159: 0.20868 | G159: 0.13995 | H159: 0.28443 | I159: 0.36453 | J159: 0.10731 | K159: 0.16681 | L159: 1.56726 | M159: 2015

Sheet 2016
A1: Country | B1: Region | C1: Happiness Rank | D1: Happiness Score | E1: Lower Confidence Interval | F1: Upper Confidence Interval | G1: Economy (GDP per Capita) | H1: Family | I1: Health (Life Expectancy) | J1: Freedom | K1: Trust (Government Corruption) | L1: Generosity | M1: Dystopia Residual | N1: Year
A2: Denmark | B2: Western Europe | C2: 1 | D2: 7.526 | E2: 7.46 | F2: 7.592 | G2: 1.44178 | H2: 1.16374 | I2: 0.79504 | J2: 0.57941 | K2: 0.44453 | L2: 0.36171 | M2: 2.73939 | N2: 2016
A3: Switzerland | B3: Western Europe | C3: 2 | D3: 7.509 | E3: 7.428 | F3: 7.59 | G3: 1.52733 | H3: 1.14524 | I3: 0.86303 | J3: 0.58557 | K3: 0.41203 | L3: 0.28083 | M3: 2.69463 | N3: 2016
A4: Iceland | B4: Western Europe | C4: 3 | D4: 7.501 | E4: 7.333 | F4: 7.669 | G4: 1.42666 | H4: 1.18326 | I4: 0.86733 | J4: 0.56624 | K4: 0.14975 | L4: 0.47678 | M4: 2.83137 | N4: 2016
A5: Norway | B5: Western Europe | C5: 4 | D5: 7.498 | E5: 7.421 | F5: 7.575 | G5: 1.57744 | H5: 1.1269 | I5: 0.79579 | J5: 0.59609 | K5: 0.35776 | L5: 0.37895 | M5: 2.66465 | N5: 2016
A6: Finland | B6: Western Europe | C6: 5 | D6: 7.413 | E6: 7.351 | F6: 7.475 | G6: 1.40598 | H6: 1.13464 | I6: 0.81091 | J6: 0.57104 | K6: 0.41004 | L6: 0.25492 | M6: 2.82596 | N6: 2016
A7: Canada | B7: North America | C7: 6 | D7: 7.404 | E7: 7.335 | F7: 7.473 | G7: 1.44015 | H7: 1.0961 | I7: 0.8276 | J7: 0.5737 | K7: 0.31329 | L7: 0.44834 | M7: 2.70485 | N7: 2016
A8: Netherlands | B8: Western Europe | C8: 7 | D8: 7.339 | E8: 7.284 | F8: 7.394 | G8: 1.46468 | H8: 1.02912 | I8: 0.81231 | J8: 0.55211 | K8: 0.29927 | L8: 0.47416 | M8: 2.70749 | N8: 2016
A9: New Zealand | B9: Australia and New Zealand | C9: 8 | D9: 7.334 | E9: 7.264 | F9: 7.404 | G9: 1.36066 | H9: 1.17278 | I9: 0.83096 | J9: 0.58147 | K9: 0.41904 | L9: 0.49401 | M9: 2.47553 | N9: 2016
A10: Australia | B10: Australia and New Zealand | C10: 9 | D10: 7.313 | E10: 7.241 | F10: 7.385 | G10: 1.44443 | H10: 1.10476 | I10: 0.8512 | J10: 0.56837 | K10: 0.32331 | L10: 0.47407 | M10: 2.5465 | N10: 2016
A11: Sweden | B11: Western Europe | C11: 10 | D11: 7.291 | E11: 7.227 | F11: 7.355 | G11: 1.45181 | H11: 1.08764 | I11: 0.83121 | J11: 0.58218 | K11: 0.40867 | L11: 0.38254 | M11: 2.54734 | N11: 2016
A12: Israel | B12: Middle East and Northern Africa | C12: 11 | D12: 7.267 | E12: 7.199 | F12: 7.335 | G12: 1.33766 | H12: 0.99537 | I12: 0.84917 | J12: 0.36432 | K12: 0.08728 | L12: 0.32288 | M12: 3.31029 | N12: 2016
A13: Austria | B13: Western Europe | C13: 12 | D13: 7.119 | E13: 7.045 | F13: 7.193 | G13: 1.45038 | H13: 1.08383 | I13: 0.80565 | J13: 0.54355 | K13: 0.21348 | L13: 0.32865 | M13: 2.69343 | N13: 2016
... A158: Burundi | B158: Sub-Saharan Africa | C158: 157 | D158: 2.905 | E158: 2.732 | F158: 3.078 | G158: 0.06831 | H158: 0.23442 | I158: 0.15747 | J158: 0.0432 | K158: 0.09419 | L158: 0.2029 | M158: 2.10404 | N158: 2016

Sheet 2017
A1: Country | B1: Happiness.Rank | C1: Region | D1: Happiness.Score | E1: Whisker.high | F1: Whisker.low | G1: Economy..GDP.per.Capita. | H1: Family | I1: Health..Life.Expectancy. | J1: Freedom | K1: Generosity | L1: Trust..Government.Corruption. | M1: Dystopia.Residual | N1: Year
A2: Norway | B2: 1 | C2: =VLOOKUP(_2017[[#This Row],[Country]],'2016'!$1:$1048576,2,FALSE) -> Western Europe | D2: 7.5370002 | E2: 7.5944448 | F2: 7.4795555 | G2: 1.6164632 | H2: 1.5335236 | I2: 0.7966665 | J2: 0.63542259 | K2: 0.36201224 | L2: 0.31596383 | M2: 2.2770267 | N2: 2017
A3: Denmark | B3: 2 | C3: =VLOOKUP(_2017[[#This Row],[Country]],'2016'!$1:$1048576,2,FALSE) -> Western Europe | D3: 7.5219998 | E3: 7.5817281 | F3: 7.4622716 | G3: 1.482383 | H3: 1.5511216 | I3: 0.79256552 | J3: 0.62600672 | K3: 0.35528049 | L3: 0.40077007 | M3: 2.3137074 | N3: 2017
A4: Iceland | B4: 3 | C4: =VLOOKUP(_2017[[#This Row],[Country]],'2016'!$1:$1048576,2,FALSE) -> Western Europe | D4: 7.5040002 | E4: 7.6220305 | F4: 7.3859699 | G4: 1.480633 | H4: 1.610574 | I4: 0.83355212 | J4: 0.62716264 | K4: 0.47554022 | L4: 0.15352656 | M4: 2.3227153 | N4: 2017
A5: Switzerland | B5: 4 | C5: =VLOOKUP(_2017[[#This Row],[Country]],'2016'!$1:$1048576,2,FALSE) -> Western Europe | D5: 7.494 | E5: 7.5617724 | F5: 7.4262275 | G5: 1.5649796 | H5: 1.5169117 | I5: 0.85813129 | J5: 0.62007058 | K5: 0.29054928 | L5: 0.36700729 | M5: 2.2767162 | N5: 2017
A6: Finland | B6: 5 | C6: =VLOOKUP(_2017[[#This Row],[Country]],'2016'!$1:$1048576,2,FALSE) -> Western Europe | D6: 7.4689999 | E6: 7.5275421 | F6: 7.4104576 | G6: 1.4435719 | H6: 1.5402467 | I6: 0.80915767 | J6: 0.61795086 | K6: 0.24548277 | L6: 0.38261154 | M6: 2.4301815 | N6: 2017
A7: Netherlands | B7: 6 | C7: =VLOOKUP(_2017[[#This Row],[Country]],'2016'!$1:$1048576,2,FALSE) -> Western Europe | D7: 7.3769999 | E7: 7.4274258 | F7: 7.3265739 | G7: 1.5039446 | H7: 1.4289392 | I7: 0.81069613 | J7: 0.58538449 | K7: 0.47048983 | L7: 0.28266183 | M7: 2.2948041 | N7: 2017
A8: Canada | B8: 7 | C8: =VLOOKUP(_2017[[#This Row],[Country]],'2016'!$1:$1048576,2,FALSE) -> North America | D8: 7.316 | E8: 7.3844028 | F8: 7.2475971 | G8: 1.4792044 | H8: 1.481349 | I8: 0.83455765 | J8: 0.61110091 | K8: 0.43553972 | L8: 0.28737152 | M8: 2.1872644 | N8: 2017
A9: New Zealand | B9: 8 | C9: =VLOOKUP(_2017[[#This Row],[Country]],'2016'!$1:$1048576,2,FALSE) -> Australia and New Zealand | D9: 7.3140001 | E9: 7.3795104 | F9: 7.2484898 | G9: 1.405706 | H9: 1.5481951 | I9: 0.81675971 | J9: 0.61406213 | K9: 0.50000513 | L9: 0.3828167 | M9: 2.0464563 | N9: 2017
A10: Sweden | B10: 9 | C10: =VLOOKUP(_2017[[#This Row],[Country]],'2016'!$1:$1048576,2,FALSE) -> Western Europe | D10: 7.2839999 | E10: 7.3440949 | F10: 7.223905 | G10: 1.4943873 | H10: 1.4781622 | I10: 0.83087516 | J10: 0.6129241 | K10: 0.38539925 | L10: 0.38439873 | M10: 2.097538 | N10: 2017
A11: Australia | B11: 10 | C11: =VLOOKUP(_2017[[#This Row],[Country]],'2016'!$1:$1048576,2,FALSE) -> Australia and New Zealand | D11: 7.2839999 | E11: 7.3566512 | F11: 7.2113486 | G11: 1.4844149 | H11: 1.510042 | I11: 0.84388679 | J11: 0.60160738 | K11: 0.47769925 | L11: 0.30118373 | M11: 2.0652108 | N11: 2017
A12: Israel | B12: 11 | C12: =VLOOKUP(_2017[[#This Row],[Country]],'2016'!$1:$1048576,2,FALSE) -> Middle East and Northern Africa | D12: 7.2129998 | E12: 7.2798533 | F12: 7.1461464 | G12: 1.3753824 | H12: 1.37629 | I12: 0.838404 | J12: 0.4059886 | K12: 0.33008265 | L12: 0.0852421 | M12: 2.8017573 | N12: 2017
A13: Costa Rica | B13: 12 | C13: =VLOOKUP(_2017[[#This Row],[Country]],'2016'!$1:$1048576,2,FALSE) -> Latin America and Caribbean | D13: 7.079 | E13: 7.1681117 | F13: 6.9898883 | G13: 1.1097063 | H13: 1.4164037 | I13: 0.75950927 | J13: 0.58013165 | K13: 0.21461323 | L13: 0.10010659 | M13: 2.8986392 | N13: 2017
... A33: Thailand | B33: 32 | C33: =VLOOKUP(_2017[[#This Row],[Country]],'2016'!$1:$1048576,2,FALSE) -> Southeastern Asia | D33: 6.4239998 | E33: 6.5091169 | F33: 6.3388827 | G33: 1.1278688 | H33: 1.4257925 | I33: 0.64723903 | J33: 0.58020073 | K33: 0.57212311 | L33: 0.031612735 | M33: 2.0395083 | N33: 2017
A34: Taiwan Province of China | B34: 33 | C34: Eastern Asia | D34: 6.4219999 | E34: 6.494596 | F34: 6.3494038 | G34: 1.4336265 | H34: 1.3845654 | I34: 0.79398423 | J34: 0.36146659 | K34: 0.25836048 | L34: 0.063829236 | M34: 2.1266074 | N34: 2017
A35: Spain | B35: 34 | C35: =VLOOKUP(_2017[[#This Row],[Country]],'2016'!$1:$1048576,2,FALSE) -> Western Europe | D35: 6.4029999 | E35: 6.4710548 | F35: 6.3349449 | G35: 1.3843979 | H35: 1.5320909 | I35: 0.8889606 | J35: 0.40878123 | K35: 0.19013357 | L35: 0.070914097 | M35: 1.9277577 | N35: 2017
A36: Qatar | B36: 35 | C36: =VLOOKUP(_2017[[#This Row],[Country]],'2016'!$1:$1048576,2,FALSE) -> Middle East and Northern Africa | D36: 6.375 | E36: 6.5684768 | F36: 6.1815232 | G36: 1.8707657 | H36: 1.2742969 | I36: 0.71009809 | J36: 0.60413098 | K36: 0.33047387 | L36: 0.43929926 | M36: 1.1454644 | N36: 2017
A37: Colombia | B37: 36 | C37: =VLOOKUP(_2017[[#This Row],[Country]],'2016'!$1:$1048576,2,FALSE) -> Latin America and Caribbean | D37: 6.3569999 | E37: 6.4520201 | F37: 6.2619797 | G37: 1.0706223 | H37: 1.4021829 | I37: 0.59502792 | J37: 0.47748742 | K37: 0.14901447 | L37: 0.046668742 | M37: 2.6160681 | N37: 2017
A38: Saudi Arabia | B38: 37 | C38: =VLOOKUP(_2017[[#This Row],[Country]],'2016'!$1:$1048576,2,FALSE) -> Middle East and Northern Africa | D38: 6.3439999 | E38: 6.4441666 | F38: 6.2438331 | G38: 1.5306236 | H38: 1.2866776 | I38: 0.59014833 | J38: 0.44975057 | K38: 0.14761601 | L38: 0.27343225 | M38: 2.0654297 | N38: 2017
A39: Trinidad and Tobago | B39: 38 | C39: =VLOOKUP(_2017[[#This Row],[Country]],'2016'!$1:$1048576,2,FALSE) -> Latin America and Caribbean | D39: 6.1680002 | E39: 6.3815339 | F39: 5.9544666 | G39: 1.3613559 | H39: 1.3802285 | I39: 0.51998329 | J39: 0.51863074 | K39: 0.32529646 | L39: 0.0089648161 | M39: 2.0532475 | N39: 2017
A40: Kuwait | B40: 39 | C40: =VLOOKUP(_2017[[#This Row],[Country]],'2016'!$1:$1048576,2,FALSE) -> Middle East and Northern Africa | D40: 6.105 | E40: 6.191957 | F40: 6.018043 | G40: 1.6329525 | H40: 1.2596987 | I40: 0.63210571 | J40: 0.49633759 | K40: 0.2282898 | L40: 0.21515955 | M40: 1.6404252 | N40: 2017
A41: Slovakia | B41: 40 | C41: =VLOOKUP(_2017[[#This Row],[Country]],'2016'!$1:$1048576,2,FALSE) -> Central and Eastern Europe | D41: 6.098 | E41: 6.1773484 | F41: 6.0186517 | G41: 1.3253936 | H41: 1.5050592 | I41: 0.71273291 | J41: 0.29581746 | K41: 0.13654448 | L41: 0.024210852 | M41: 2.0977767 | N41: 2017
A42: Bahrain | B42: 41 | C42: =VLOOKUP(_2017[[#This Row],[Country]],'2016'!$1:$1048576,2,FALSE) -> Middle East and Northern Africa | D42: 6.0869999 | E42: 6.1789891 | F42: 5.9950107 | G42: 1.4884123 | H42: 1.3231105 | I42: 0.65313303 | J42: 0.53674692 | K42: 0.17266849 | L42: 0.25704217 | M42: 1.6561494 | N42: 2017
A43: Malaysia | B43: 42 | C43: =VLOOKUP(_2017[[#This Row],[Country]],'2016'!$1:$1048576,2,FALSE) -> Southeastern Asia | D43: 6.0840001 | E43: 6.1799796 | F43: 5.9880206 | G43: 1.2912154 | H43: 1.284646 | I43: 0.61878443 | J43: 0.40226498 | K43: 0.41660893 | L43: 0.065600708 | M43: 2.0044489 | N43: 2017
A44: Nicaragua | B44: 43 | C44: =VLOOKUP(_2017[[#This Row],[Country]],'2016'!$1:$1048576,2,FALSE) -> Latin America and Caribbean | D44: 6.0710001 | E44: 6.1865836 | F44: 5.9554166 | G44: 0.7372992 | H44: 1.2872157 | I44: 0.65309596 | J44: 0.44755185 | K44: 0.30167422 | L44: 0.13068798 | M44: 2.5139306 | N44: 2017
A45: Ecuador | B45: 44 | C45: =VLOOKUP(_2017[[#This Row],[Country]],'2016'!$1:$1048576,2,FALSE) -> Latin America and Caribbean | D45: 6.0079999 | E45: 6.1058477 | F45: 5.9101521 | G45: 1.0008204 | H45: 1.2861688 | I45: 0.68563622 | J45: 0.4551982 | K45: 0.15011247 | L45: 0.14013465 | M45: 2.2903526 | N45: 2017
A46: El Salvador | B46: 45 | C46: =VLOOKUP(_2017[[#This Row],[Country]],'2016'!$1:$1048576,2,FALSE) -> Latin America and Caribbean | D46: 6.0029998 | E46: 6.1086351 | F46: 5.8973644 | G46: 0.9097845 | H46: 1.1821251 | I46: 0.59601855 | J46: 0.43245253 | K46: 0.078257985 | L46: 0.08998096 | M46: 2.7145939 | N46: 2017
... A71: Paraguay | B71: 70 | C71: =VLOOKUP(_2017[[#This Row],[Country]],'2016'!$1:$1048576,2,FALSE) -> Latin America and Caribbean | D71: 5.493 | E71: 5.5773813 | F71: 5.4086188 | G71: 0.93253732 | H71: 1.5072849 | I71: 0.57925069 | J71: 0.47350779 | K71: 0.22415066 | L71: 0.091065913 | M71: 1.6853335 | N71: 2017
A72: Hong Kong S.A.R., China | B72: 71 | C72: Eastern Asia | D72: 5.4720001 | E72: 5.5495942 | F72: 5.3944061 | G72: 1.5516748 | H72: 1.2627909 | I72: 0.94306242 | J72: 0.49096864 | K72: 0.37446579 | L72: 0.29393375 | M72: 0.55463314 | N72: 2017
A73: Philippines | B73: 72 | C73: =VLOOKUP(_2017[[#This Row],[Country]],'2016'!$1:$1048576,2,FALSE) -> Southeastern Asia | D73: 5.4299998 | E73: 5.5453351 | F73: 5.3146646 | G73: 0.85769922 | H73: 1.2539176 | I73: 0.46800905 | J73: 0.58521467 | K73: 0.19351342 | L73: 0.099331893 | M73: 1.9726048 | N73: 2017
A74: Serbia | B74: 73 | C74: =VLOOKUP(_2017[[#This Row],[Country]],'2016'!$1:$1048576,2,FALSE) -> Central and Eastern Europe | D74: 5.395 | E74: 5.4915697 | F74: 5.2984303 | G74: 1.0693176 | H74: 1.2581898 | I74: 0.65078467 | J74: 0.20871553 | K74: 0.22012588 | L74: 0.040903781 | M74: 1.9470844 | N74: 2017
A75: Jordan | B75: 74 | C75: =VLOOKUP(_2017[[#This Row],[Country]],'2016'!$1:$1048576,2,FALSE) -> Middle East and Northern Africa | D75: 5.336 | E75: 5.44841 | F75: 5.2235899 | G75: 0.99101239 | H75: 1.2390889 | I75: 0.60459006 | J75: 0.41842115 | K75: 0.17217046 | L75: 0.11980327 | M75: 1.7911766 | N75: 2017
A76: Hungary | B76: 75 | C76: =VLOOKUP(_2017[[#This Row],[Country]],'2016'!$1:$1048576,2,FALSE) -> Central and Eastern Europe | D76: 5.3239999 | E76: 5.4030397 | F76: 5.2449601 | G76: 1.2860119 | H76: 1.3431331 | I76: 0.68776345 | J76: 0.17586352 | K76: 0.078401662 | L76: 0.036636937 | M76: 1.7164593 | N76: 2017
A77: Jamaica | B77: 76 | C77: =VLOOKUP(_2017[[#This Row],[Country]],'2016'!$1:$1048576,2,FALSE) -> Latin America and Caribbean | D77: 5.3109999 | E77: 5.5813987 | F77: 5.040601 | G77: 0.92557931 | H77: 1.3682181 | I77: 0.64102238 | J77: 0.47430724 | K77: 0.23381834 | L77: 0.055267781 | M77: 1.6123257 | N77: 2017
A78: Croatia | B78: 77 | C78: =VLOOKUP(_2017[[#This Row],[Country]],'2016'!$1:$1048576,2,FALSE) -> Central and Eastern Europe | D78: 5.2930002 | E78: 5.3917772 | F78: 5.1942232 | G78: 1.2225562 | H78: 0.96798301 | I78: 0.70128852 | J78: 0.25577229 | K78: 0.24800298 | L78: 0.04310311 | M78: 1.8544924 | N78: 2017
A79: Kosovo | B79: 78 | C79: =VLOOKUP(_2017[[#This Row],[Country]],'2016'!$1:$1048576,2,FALSE) -> Central and Eastern Europe | D79: 5.2789998 | E79: 5.364848 | F79: 5.1931516 | G79: 0.95148438 | H79: 1.1378535 | I79: 0.54145205 | J79: 0.26028794 | K79: 0.31993145 | L79: 0.057471618 | M79: 2.0105407 | N79: 2017
A80: China | B80: 79 | C80: =VLOOKUP(_2017[[#This Row],[Country]],'2016'!$1:$1048576,2,FALSE) -> Eastern Asia | D80: 5.2729998 | E80: 5.3192781 | F80: 5.2267214 | G80: 1.0811658 | H80: 1.1608374 | I80: 0.7414155 | J80: 0.47278771 | K80: 0.028806841 | L80: 0.022794275 | M80: 1.7649386 | N80: 2017
A81: Pakistan | B81: 80 | C81: =VLOOKUP(_2017[[#This Row],[Country]],'2016'!$1:$1048576,2,FALSE) -> Southern Asia | D81: 5.2690001 | E81: 5.3599836 | F81: 5.1780165 | G81: 0.72688353 | H81: 0.67269069 | I81: 0.40204778 | J81: 0.23521526 | K81: 0.31544602 | L81: 0.12434807 | M81: 2.7924893 | N81: 2017
A82: Indonesia | B82: 81 | C82: =VLOOKUP(_2017[[#This Row],[Country]],'2016'!$1:$1048576,2,FALSE) -> Southeastern Asia | D82: 5.2620001 | E82: 5.3528886 | F82: 5.1711116 | G82: 0.99553859 | H82: 1.2744447 | I82: 0.49234572 | J82: 0.44332346 | K82: 0.61170459 | L82: 0.015317135 | M82: 1.429477 | N82: 2017
A83: Venezuela | B83: 82 | C83: =VLOOKUP(_2017[[#This Row],[Country]],'2016'!$1:$1048576,2,FALSE) -> Latin America and Caribbean | D83: 5.25 | E83: 5.3700319 | F83: 5.1299681 | G83: 1.1284312 | H83: 1.4313376 | I83: 0.61714423 | J83: 0.15399712 | K83: 0.06501963 | L83: 0.064491123 | M83: 1.7894638 | N83: 2017
...

Sheet 2018
A1: Overall rank | B1: Country or region | C1: Region | D1: Score | E1: GDP per capita | F1: Social support | G1: Healthy life expectancy | H1: Freedom to make life choices | I1: Generosity | J1: Perceptions of corruption | K1: Year
A2: 1 | B2: Finland | C2: =VLOOKUP(_2018[[#This Row],[Country or region]],'2016'!$1:$1048576,2,FALSE) -> Western Europe | D2: 7.632 | E2: 1.305 | F2: 1.592 | G2: 0.874 | H2: 0.681 | I2: 0.202 | J2: 0.393 | K2: 2018
A3: 2 | B3: Norway | C3: =VLOOKUP(_2018[[#This Row],[Country or region]],'2016'!$1:$1048576,2,FALSE) -> Western Europe | D3: 7.594 | E3: 1.456 | F3: 1.582 | G3: 0.861 | H3: 0.686 | I3: 0.286 | J3: 0.340 | K3: 2018
A4: 3 | B4: Denmark | C4: =VLOOKUP(_2018[[#This Row],[Country or region]],'2016'!$1:$1048576,2,FALSE) -> Western Europe | D4: 7.555 | E4: 1.351 | F4: 1.59 | G4: 0.868 | H4: 0.683 | I4: 0.284 | J4: 0.408 | K4: 2018
A5: 4 | B5: Iceland | C5: =VLOOKUP(_2018[[#This Row],[Country or region]],'2016'!$1:$1048576,2,FALSE) -> Western Europe | D5: 7.495 | E5: 1.343 | F5: 1.644 | G5: 0.914 | H5: 0.677 | I5: 0.353 | J5: 0.138 | K5: 2018
A6: 5 | B6: Switzerland | C6: =VLOOKUP(_2018[[#This Row],[Country or region]],'2016'!$1:$1048576,2,FALSE) -> Western Europe | D6: 7.487 | E6: 1.42 | F6: 1.549 | G6: 0.927 | H6: 0.66 | I6: 0.256 | J6: 0.357 | K6: 2018
A7: 6 | B7: Netherlands | C7: =VLOOKUP(_2018[[#This Row],[Country or region]],'2016'!$1:$1048576,2,FALSE) -> Western Europe | D7: 7.441 | E7: 1.361 | F7: 1.488 | G7: 0.878 | H7: 0.638 | I7: 0.333 | J7: 0.295 | K7: 2018
A8: 7 | B8: Canada | C8: =VLOOKUP(_2018[[#This Row],[Country or region]],'2016'!$1:$1048576,2,FALSE) -> North America | D8: 7.328 | E8: 1.33 | F8: 1.532 | G8: 0.896 | H8: 0.653 | I8: 0.321 | J8: 0.291 | K8: 2018
A9: 8 | B9: New Zealand | C9: =VLOOKUP(_2018[[#This Row],[Country or region]],'2016'!$1:$1048576,2,FALSE) -> Australia and New Zealand | D9: 7.324 | E9: 1.268 | F9: 1.601 | G9: 0.876 | H9: 0.669 | I9: 0.365 | J9: 0.389 | K9: 2018
A10: 9 | B10: Sweden | C10: =VLOOKUP(_2018[[#This Row],[Country or region]],'2016'!$1:$1048576,2,FALSE) -> Western Europe | D10: 7.314 | E10: 1.355 | F10: 1.501 | G10: 0.913 | H10: 0.659 | I10: 0.285 | J10: 0.383 | K10: 2018
A11: 10 | B11: Australia | C11: =VLOOKUP(_2018[[#This Row],[Country or region]],'2016'!$1:$1048576,2,FALSE) -> Australia and New Zealand | D11: 7.272 | E11: 1.34 | F11: 1.573 | G11: 0.91 | H11: 0.647 | I11: 0.361 | J11: 0.302 | K11: 2018
A12: 11 | B12: United Kingdom | C12: =VLOOKUP(_2018[[#This Row],[Country or region]],'2016'!$1:$1048576,2,FALSE) -> Western Europe | D12: 7.19 | E12: 1.244 | F12: 1.433 | G12: 0.888 | H12: 0.464 | I12: 0.262 | J12: 0.082 | K12: 2018
A13: 12 | B13: Austria | C13: =VLOOKUP(_2018[[#This Row],[Country or region]],'2016'!$1:$1048576,2,FALSE) -> Western Europe | D13: 7.139 | E13: 1.341 | F13: 1.504 | G13: 0.891 | H13: 0.617 | I13: 0.242 | J13: 0.224 | K13: 2018
... A38: 37 | B38: Colombia | C38: =VLOOKUP(_2018[[#This Row],[Country or region]],'2016'!$1:$1048576,2,FALSE) -> Latin America and Caribbean | D38: 6.26 | E38: 0.96 | F38: 1.439 | G38: 0.635 | H38: 0.531 | I38: 0.099 | J38: 0.039 | K38: 2018
A39: 38 | B39: Trinidad & Tobago | C39: Latin America and Caribbean | D39: 6.192 | E39: 1.223 | F39: 1.492 | G39: 0.564 | H39: 0.575 | I39: 0.171 | J39: 0.019 | K39: 2018
A40: 39 | B40: Slovakia | C40: =VLOOKUP(_2018[[#This Row],[Country or region]],'2016'!$1:$1048576,2,FALSE) -> Central and Eastern Europe | D40: 6.173 | E40: 1.21 | F40: 1.537 | G40: 0.776 | H40: 0.354 | I40: 0.118 | J40: 0.014 | K40: 2018
A41: 40 | B41: El Salvador | C41: =VLOOKUP(_2018[[#This Row],[Country or region]],'2016'!$1:$1048576,2,FALSE) -> Latin America and Caribbean | D41: 6.167 | E41: 0.806 | F41: 1.231 | G41: 0.639 | H41: 0.461 | I41: 0.065 | J41: 0.082 | K41: 2018
A42: 41 | B42: Nicaragua | C42: =VLOOKUP(_2018[[#This Row],[Country or region]],'2016'!$1:$1048576,2,FALSE) -> Latin America and Caribbean | D42: 6.141 | E42: 0.668 | F42: 1.319 | G42: 0.7 | H42: 0.527 | I42: 0.208 | J42: 0.128 | K42: 2018
A43: 42 | B43: Poland | C43: =VLOOKUP(_2018[[#This Row],[Country or region]],'2016'!$1:$1048576,2,FALSE) -> Central and Eastern Europe | D43: 6.123 | E43: 1.176 | F43: 1.448 | G43: 0.781 | H43: 0.546 | I43: 0.108 | J43: 0.064 | K43: 2018
A44: 43 | B44: Bahrain | C44: =VLOOKUP(_2018[[#This Row],[Country or region]],'2016'!$1:$1048576,2,FALSE) -> Middle East and Northern Africa | D44: 6.105 | E44: 1.338 | F44: 1.366 | G44: 0.698 | H44: 0.594 | I44: 0.243 | J44: 0.123 | K44: 2018
A45: 44 | B45: Uzbekistan | C45: =VLOOKUP(_2018[[#This Row],[Country or region]],'2016'!$1:$1048576,2,FALSE) -> Central and Eastern Europe | D45: 6.096 | E45: 0.719 | F45: 1.584 | G45: 0.605 | H45: 0.724 | I45: 0.328 | J45: 0.259 | K45: 2018
A46: 45 | B46: Kuwait | C46: =VLOOKUP(_2018[[#This Row],[Country or region]],'2016'!$1:$1048576,2,FALSE) -> Middle East and Northern Africa | D46: 6.083 | E46: 1.474 | F46: 1.301 | G46: 0.675 | H46: 0.554 | I46: 0.167 | J46: 0.106 | K46: 2018
A47: 46 | B47: Thailand | C47: =VLOOKUP(_2018[[#This Row],[Country or region]],'2016'!$1:$1048576,2,FALSE) -> Southeastern Asia | D47: 6.072 | E47: 1.016 | F47: 1.417 | G47: 0.707 | H47: 0.637 | I47: 0.364 | J47: 0.029 | K47: 2018
A48: 47 | B48: Italy | C48: =VLOOKUP(_2018[[#This Row],[Country or region]],'2016'!$1:$1048576,2,FALSE) -> Western Europe | D48: 6 | E48: 1.264 | F48: 1.501 | G48: 0.946 | H48: 0.281 | I48: 0.137 | J48: 0.028 | K48: 2018
A49: 48 | B49: Ecuador | C49: =VLOOKUP(_2018[[#This Row],[Country or region]],'2016'!$1:$1048576,2,FALSE) -> Latin America and Caribbean | D49: 5.973 | E49: 0.889 | F49: 1.33 | G49: 0.736 | H49: 0.556 | I49: 0.114 | J49: 0.120 | K49: 2018
A50: 49 | B50: Belize | C50: =VLOOKUP(_2018[[#This Row],[Country or region]],'2016'!$1:$1048576,2,FALSE) -> Latin America and Caribbean | D50: 5.956 | E50: 0.807 | F50: 1.101 | G50: 0.474 | H50: 0.593 | I50: 0.183 | J50: 0.089 | K50: 2018
A51: 50 | B51: Lithuania | C51: =VLOOKUP(_2018[[#This Row],[Country or region]],'2016'!$1:$1048576,2,FALSE) -> Central and Eastern Europe | D51: 5.952 | E51: 1.197 | F51: 1.527 | G51: 0.716 | H51: 0.35 | I51: 0.026 | J51: 0.006 | K51: 2018
... A58: 57 | B58: South Korea | C58: =VLOOKUP(_2018[[#This Row],[Country or region]],'2016'!$1:$1048576,2,FALSE) -> Eastern Asia | D58: 5.875 | E58: 1.266 | F58: 1.204 | G58: 0.955 | H58: 0.244 | I58: 0.175 | J58: 0.051 | K58: 2018
A59: 58 | B59: Northern Cyprus | C59: Western Europe | D59: 5.835 | E59: 1.229 | F59: 1.211 | G59: 0.909 | H59: 0.495 | I59: 0.179 | J59: 0.154 | K59: 2018
A60: 59 | B60: Russia | C60: =VLOOKUP(_2018[[#This Row],[Country or region]],'2016'!$1:$1048576,2,FALSE) -> Central and Eastern Europe | D60: 5.81 | E60: 1.151 | F60: 1.479 | G60: 0.599 | H60: 0.399 | I60: 0.065 | J60: 0.025 | K60: 2018
A61: 60 | B61: Kazakhstan | C61: =VLOOKUP(_2018[[#This Row],[Country or region]],'2016'!$1:$1048576,2,FALSE) -> Central and Eastern Europe | D61: 5.79 | E61: 1.143 | F61: 1.516 | G61: 0.631 | H61: 0.454 | I61: 0.148 | J61: 0.121 | K61: 2018
A62: 61 | B62: Cyprus | C62: =VLOOKUP(_2018[[#This Row],[Country or region]],'2016'!$1:$1048576,2,FALSE) -> Western Europe | D62: 5.762 | E62: 1.229 | F62: 1.191 | G62: 0.909 | H62: 0.423 | I62: 0.202 | J62: 0.035 | K62: 2018
A63: 62 | B63: Bolivia | C63: =VLOOKUP(_2018[[#This Row],[Country or region]],'2016'!$1:$1048576,2,FALSE) -> Latin America and Caribbean | D63: 5.752 | E63: 0.751 | F63: 1.223 | G63: 0.508 | H63: 0.606 | I63: 0.141 | J63: 0.054 | K63: 2018
A64: 63 | B64: Estonia | C64: =VLOOKUP(_2018[[#This Row],[Country or region]],'2016'!$1:$1048576,2,FALSE) -> Central and Eastern Europe | D64: 5.739 | E64: 1.2 | F64: 1.532 | G64: 0.737 | H64: 0.553 | I64: 0.086 | J64: 0.174 | K64: 2018
A65: 64 | B65: Paraguay | C65: =VLOOKUP(_2018[[#This Row],[Country or region]],'2016'!$1:$1048576,2,FALSE) -> Latin America and Caribbean | D65: 5.681 | E65: 0.835 | F65: 1.522 | G65: 0.615 | H65: 0.541 | I65: 0.162 | J65: 0.074 | K65: 2018
A66: 65 | B66: Peru | C66: =VLOOKUP(_2018[[#This Row],[Country or region]],'2016'!$1:$1048576,2,FALSE) -> Latin America and Caribbean | D66: 5.663 | E66: 0.934 | F66: 1.249 | G66: 0.674 | H66: 0.53 | I66: 0.092 | J66: 0.034 | K66: 2018
A67: 66 | B67: Kosovo | C67: =VLOOKUP(_2018[[#This Row],[Country or region]],'2016'!$1:$1048576,2,FALSE) -> Central and Eastern Europe | D67: 5.662 | E67: 0.855 | F67: 1.23 | G67: 0.578 | H67: 0.448 | I67: 0.274 | J67: 0.023 | K67: 2018
A68: 67 | B68: Moldova | C68: =VLOOKUP(_2018[[#This Row],[Country or region]],'2016'!$1:$1048576,2,FALSE) -> Central and Eastern Europe | D68: 5.64 | E68: 0.657 | F68: 1.301 | G68: 0.62 | H68: 0.232 | I68: 0.171 | J68: 0.000 | K68: 2018
A69: 68 | B69: Turkmenistan | C69: =VLOOKUP(_2018[[#This Row],[Country or region]],'2016'!$1:$1048576,2,FALSE) -> Central and Eastern Europe | D69: 5.636 | E69: 1.016 | F69: 1.533 | G69: 0.517 | H69: 0.417 | I69: 0.199 | J69: 0.037 | K69: 2018
A70: 69 | B70: Hungary | C70: =VLOOKUP(_2018[[#This Row],[Country or region]],'2016'!$1:$1048576,2,FALSE) -> Central and Eastern Europe | D70: 5.62 | E70: 1.171 | F70: 1.401 | G70: 0.732 | H70: 0.259 | I70: 0.061 | J70: 0.022 | K70: 2018
...

Sheet 2019
A1: Overall rank | B1: Country or region | C1: Region | D1: Score | E1: GDP per capita | F1: Social support | G1: Healthy life expectancy | H1: Freedom to make life choices | I1: Generosity | J1: Perceptions of corruption | K1: Year
A2: 1 | B2: Finland | C2: =VLOOKUP(_2019[[#This Row],[Country or region]],'2016'!$1:$1048576,2,FALSE) -> Western Europe | D2: 7.769 | E2: 1.34 | F2: 1.587 | G2: 0.986 | H2: 0.596 | I2: 0.153 | J2: 0.393 | K2: 2019
A3: 2 | B3: Denmark | C3: =VLOOKUP(_2019[[#This Row],[Country or region]],'2016'!$1:$1048576,2,FALSE) -> Western Europe | D3: 7.6 | E3: 1.383 | F3: 1.573 | G3: 0.996 | H3: 0.592 | I3: 0.252 | J3: 0.41 | K3: 2019
A4: 3 | B4: Norway | C4: =VLOOKUP(_2019[[#This Row],[Country or region]],'2016'!$1:$1048576,2,FALSE) -> Western Europe | D4: 7.554 | E4: 1.488 | F4: 1.582 | G4: 1.028 | H4: 0.603 | I4: 0.271 | J4: 0.341 | K4: 2019
A5: 4 | B5: Iceland | C5: =VLOOKUP(_2019[[#This Row],[Country or region]],'2016'!$1:$1048576,2,FALSE) -> Western Europe | D5: 7.494 | E5: 1.38 | F5: 1.624 | G5: 1.026 | H5: 0.591 | I5: 0.354 | J5: 0.118 | K5: 2019
A6: 5 | B6: Netherlands | C6: =VLOOKUP(_2019[[#This Row],[Country or region]],'2016'!$1:$1048576,2,FALSE) -> Western Europe | D6: 7.488 | E6: 1.396 | F6: 1.522 | G6: 0.999 | H6: 0.557 | I6: 0.322 | J6: 0.298 | K6: 2019
A7: 6 | B7: Switzerland | C7: =VLOOKUP(_2019[[#This Row],[Country or region]],'2016'!$1:$1048576,2,FALSE) -> Western Europe | D7: 7.48 | E7: 1.452 | F7: 1.526 | G7: 1.052 | H7: 0.572 | I7: 0.263 | J7: 0.343 | K7: 2019
A8: 7 | B8: Sweden | C8: =VLOOKUP(_2019[[#This Row],[Country or region]],'2016'!$1:$1048576,2,FALSE) -> Western Europe | D8: 7.343 | E8: 1.387 | F8: 1.487 | G8: 1.009 | H8: 0.574 | I8: 0.267 | J8: 0.373 | K8: 2019
A9: 8 | B9: New Zealand | C9: =VLOOKUP(_2019[[#This Row],[Country or region]],'2016'!$1:$1048576,2,FALSE) -> Australia and New Zealand | D9: 7.307 | E9: 1.303 | F9: 1.557 | G9: 1.026 | H9: 0.585 | I9: 0.33 | J9: 0.38 | K9: 2019
A10: 9 | B10: Canada | C10: =VLOOKUP(_2019[[#This Row],[Country or region]],'2016'!$1:$1048576,2,FALSE) -> North America | D10: 7.278 | E10: 1.365 | F10: 1.505 | G10: 1.039 | H10: 0.584 | I10: 0.285 | J10: 0.308 | K10: 2019
A11: 10 | B11: Austria | C11: =VLOOKUP(_2019[[#This Row],[Country or region]],'2016'!$1:$1048576,2,FALSE) -> Western Europe | D11: 7.246 | E11: 1.376 | F11: 1.475 | G11: 1.016 | H11: 0.532 | I11: 0.244 | J11: 0.226 | K11: 2019
A12: 11 | B12: Australia | C12: =VLOOKUP(_2019[[#This Row],[Country or region]],'2016'!$1:$1048576,2,FALSE) -> Australia and New Zealand | D12: 7.228 | E12: 1.372 | F12: 1.548 | G12: 1.036 | H12: 0.557 | I12: 0.332 | J12: 0.29 | K12: 2019
A13: 12 | B13: Costa Rica | C13: =VLOOKUP(_2019[[#This Row],[Country or region]],'2016'!$1:$1048576,2,FALSE) -> Latin America and Caribbean | D13: 7.167 | E13: 1.034 | F13: 1.441 | G13: 0.963 | H13: 0.558 | I13: 0.144 | J13: 0.093 | K13: 2019
... A39: 38 | B39: Slovakia | C39: =VLOOKUP(_2019[[#This Row],[Country or region]],'2016'!$1:$1048576,2,FALSE) -> Central and Eastern Europe | D39: 6.198 | E39: 1.246 | F39: 1.504 | G39: 0.881 | H39: 0.334 | I39: 0.121 | J39: 0.014 | K39: 2019
A40: 39 | B40: Trinidad & Tobago | C40: Latin America and Caribbean | D40: 6.192 | E40: 1.231 | F40: 1.477 | G40: 0.713 | H40: 0.489 | I40: 0.185 | J40: 0.016 | K40: 2019
A41: 40 | B41: Poland | C41: =VLOOKUP(_2019[[#This Row],[Country or region]],'2016'!$1:$1048576,2,FALSE) -> Central and Eastern Europe | D41: 6.182 | E41: 1.206 | F41: 1.438 | G41: 0.884 | H41: 0.483 | I41: 0.117 | J41: 0.05 | K41: 2019
A42: 41 | B42: Uzbekistan | C42: =VLOOKUP(_2019[[#This Row],[Country or region]],'2016'!$1:$1048576,2,FALSE) -> Central and Eastern Europe | D42: 6.174 | E42: 0.745 | F42: 1.529 | G42: 0.756 | H42: 0.631 | I42: 0.322 | J42: 0.24 | K42: 2019
A43: 42 | B43: Lithuania | C43: =VLOOKUP(_2019[[#This Row],[Country or region]],'2016'!$1:$1048576,2,FALSE) -> Central and Eastern Europe | D43: 6.149 | E43: 1.238 | F43: 1.515 | G43: 0.818 | H43: 0.291 | I43: 0.043 | J43: 0.042 | K43: 2019
A44: 43 | B44: Colombia | C44: =VLOOKUP(_2019[[#This Row],[Country or region]],'2016'!$1:$1048576,2,FALSE) -> Latin America and Caribbean | D44: 6.125 | E44: 0.985 | F44: 1.41 | G44: 0.841 | H44: 0.47 | I44: 0.099 | J44: 0.034 | K44: 2019
A45: 44 | B45: Slovenia | C45: =VLOOKUP(_2019[[#This Row],[Country or region]],'2016'!$1:$1048576,2,FALSE) -> Central and Eastern Europe | D45: 6.118 | E45: 1.258 | F45: 1.523 | G45: 0.953 | H45: 0.564 | I45: 0.144 | J45: 0.057 | K45: 2019
A46: 45 | B46: Nicaragua | C46: =VLOOKUP(_2019[[#This Row],[Country or region]],'2016'!$1:$1048576,2,FALSE) -> Latin America and Caribbean | D46: 6.105 | E46: 0.694 | F46: 1.325 | G46: 0.835 | H46: 0.435 | I46: 0.2 | J46: 0.127 | K46: 2019
A47: 46 | B47: Kosovo | C47: =VLOOKUP(_2019[[#This Row],[Country or region]],'2016'!$1:$1048576,2,FALSE) -> Central and Eastern Europe | D47: 6.1 | E47: 0.882 | F47: 1.232 | G47: 0.758 | H47: 0.489 | I47: 0.262 | J47: 0.006 | K47: 2019
A48: 47 | B48: Argentina | C48: =VLOOKUP(_2019[[#This Row],[Country or region]],'2016'!$1:$1048576,2,FALSE) -> Latin America and Caribbean | D48: 6.086 | E48: 1.092 | F48: 1.432 | G48: 0.881 | H48: 0.471 | I48: 0.066 | J48: 0.05 | K48: 2019
A49: 48 | B49: Romania | C49: =VLOOKUP(_2019[[#This Row],[Country or region]],'2016'!$1:$1048576,2,FALSE) -> Central and Eastern Europe | D49: 6.07 | E49: 1.162 | F49: 1.232 | G49: 0.825 | H49: 0.462 | I49: 0.083 | J49: 0.005 | K49: 2019
A50: 49 | B50: Cyprus | C50: =VLOOKUP(_2019[[#This Row],[Country or region]],'2016'!$1:$1048576,2,FALSE) -> Western Europe | D50: 6.046 | E50: 1.263 | F50: 1.223 | G50: 1.042 | H50: 0.406 | I50: 0.19 | J50: 0.041 | K50: 2019
A51: 50 | B51: Ecuador | C51: =VLOOKUP(_2019[[#This Row],[Country or region]],'2016'!$1:$1048576,2,FALSE) -> Latin America and Caribbean | D51: 6.028 | E51: 0.912 | F51: 1.312 | G51: 0.868 | H51: 0.498 | I51: 0.126 | J51: 0.087 | K51: 2019
A52: 51 | B52: Kuwait | C52: =VLOOKUP(_2019[[#This Row],[Country or region]],'2016'!$1:$1048576,2,FALSE) -> Middle East and Northern Africa | D52: 6.021 | E52: 1.5 | F52: 1.319 | G52: 0.808 | H52: 0.493 | I52: 0.142 | J52: 0.097 | K52: 2019
... A64: 63 | B64: Paraguay | C64: =VLOOKUP(_2019[[#This Row],[Country or region]],'2016'!$1:$1048576,2,FALSE) -> Latin America and Caribbean | D64: 5.743 | E64: 0.855 | F64: 1.475 | G64: 0.777 | H64: 0.514 | I64: 0.184 | J64: 0.08 | K64: 2019
A65: 64 | B65: Northern Cyprus | C65: Western Europe | D65: 5.718 | E65: 1.263 | F65: 1.252 | G65: 1.042 | H65: 0.417 | I65: 0.191 | J65: 0.162 | K65: 2019
A66: 65 | B66: Peru | C66: =VLOOKUP(_2019[[#This Row],[Country or region]],'2016'!$1:$1048576,2,FALSE) -> Latin America and Caribbean | D66: 5.697 | E66: 0.96 | F66: 1.274 | G66: 0.854 | H66: 0.455 | I66: 0.083 | J66: 0.027 | K66: 2019
A67: 66 | B67: Portugal | C67: =VLOOKUP(_2019[[#This Row],[Country or region]],'2016'!$1:$1048576,2,FALSE) -> Western Europe | D67: 5.693 | E67: 1.221 | F67: 1.431 | G67: 0.999 | H67: 0.508 | I67: 0.047 | J67: 0.025 | K67: 2019
A68: 67 | B68: Pakistan | C68: =VLOOKUP(_2019[[#This Row],[Country or region]],'2016'!$1:$1048576,2,FALSE) -> Southern Asia | D68: 5.653 | E68: 0.677 | F68: 0.886 | G68: 0.535 | H68: 0.313 | I68: 0.22 | J68: 0.098 | K68: 2019
A69: 68 | B69: Russia | C69: =VLOOKUP(_2019[[#This Row],[Country or region]],'2016'!$1:$1048576,2,FALSE) -> Central and Eastern Europe | D69: 5.648 | E69: 1.183 | F69: 1.452 | G69: 0.726 | H69: 0.334 | I69: 0.082 | J69: 0.031 | K69: 2019
A70: 69 | B70: Philippines | C70: =VLOOKUP(_2019[[#This Row],[Country or region]],'2016'!$1:$1048576,2,FALSE) -> Southeastern Asia | D70: 5.631 | E70: 0.807 | F70: 1.293 | G70: 0.657 | H70: 0.558 | I70: 0.117 | J70: 0.107 | K70: 2019
A71: 70 | B71: Serbia | C71: =VLOOKUP(_2019[[#This Row],[Country or region]],'2016'!$1:$1048576,2,FALSE) -> Central and Eastern Europe | D71: 5.603 | E71: 1.004 | F71: 1.383 | G71: 0.854 | H71: 0.282 | I71: 0.137 | J71: 0.039 | K71: 2019
A72: 71 | B72: Moldova | C72: =VLOOKUP(_2019[[#This Row],[Country or region]],'2016'!$1:$1048576,2,FALSE) -> Central and Eastern Europe | D72: 5.529 | E72: 0.685 | F72: 1.328 | G72: 0.739 | H72: 0.245 | I72: 0.181 | J72: 0 | K72: 2019
A73: 72 | B73: Libya | C73: =VLOOKUP(_2019[[#This Row],[Country or region]],'2016'!$1:$1048576,2,FALSE) -> Middle East and Northern Africa | D73: 5.525 | E73: 1.044 | F73: 1.303 | G73: 0.673 | H73: 0.416 | I73: 0.133 | J73: 0.152 | K73: 2019
A74: 73 | B74: Montenegro | C74: =VLOOKUP(_2019[[#This Row],[Country or region]],'2016'!$1:$1048576,2,FALSE) -> Central and Eastern Europe | D74: 5.523 | E74: 1.051 | F74: 1.361 | G74: 0.871 | H74: 0.197 | I74: 0.142 | J74: 0.08 | K74: 2019
A75: 74 | B75: Tajikistan | C75: =VLOOKUP(_2019[[#This Row],[Country or region]],'2016'!$1:$1048576,2,FALSE) -> Central and Eastern Europe | D75: 5.467 | E75: 0.493 | F75: 1.098 | G75: 0.718 | H75: 0.389 | I75: 0.23 | J75: 0.144 | K75: 2019
A76: 75 | B76: Croatia | C76: =VLOOKUP(_2019[[#This Row],[Country or region]],'2016'!$1:$1048576,2,FALSE) -> Central and Eastern Europe | D76: 5.432 | E76: 1.155 | F76: 1.266 | G76: 0.914 | H76: 0.296 | I76: 0.119 | J76: 0.022 | K76: 2019
...

Sheet Sheet1
